Fix these failing tests:
DEBUG    peewee:peewee.py:3319 ('CREATE INDEX IF NOT EXISTS "researchnote_human_input_id" ON "research_note" ("human_input_id")', [])
DEBUG    peewee:peewee.py:3319 ('CREATE INDEX IF NOT EXISTS "researchnote_session_id" ON "research_note" ("session_id")', [])
DEBUG    peewee:peewee.py:3319 ('CREATE TABLE IF NOT EXISTS "trajectory" ("id" INTEGER NOT NULL PRIMARY KEY, "created_at" DATETIME NOT NULL, "updated_at" DATETIME NOT NULL, "hum
DEBUG    peewee:peewee.py:3319 ('CREATE INDEX IF NOT EXISTS "trajectory_human_input_id" ON "trajectory" ("human_input_id")', [])
DEBUG    peewee:peewee.py:3319 ('CREATE INDEX IF NOT EXISTS "trajectory_session_id" ON "trajectory" ("session_id")', [])
DEBUG    ra_aid.ra_aid.database.models:models.py:58 Ensured database tables exist
----------------------------------------------------------------------------- Captured log teardown -----------------------------------------------------------------------------
INFO     ra_aid.ra_aid.database.connection:connection.py:401 Database connection closed successfully
=================================================================================== FAILURES ====================================================================================
______________________________________________________________________ test_escalate_context_length_error _______________________________________________________________________

capsys = <_pytest.capture.CaptureFixture object at 0x7173aa0b9f40>

    def test_escalate_context_length_error(capsys):
        escalate_context_length_error("context length exceeded")
        out = capsys.readouterr().out + capsys.readouterr().err
        assert "context length error" in out
        assert "Manual intervention required" in out
>       assert "Last error: context length exceeded" in out
E       AssertionError: assert 'Last error: context length exceeded' in '╭─────────────────────────────────── Error ────────────────────────────────────╮
│ [context length erro

tests/ra_aid/test_credit_ui_helpers.py:45: AssertionError
=============================================================================== warnings summary ================================================================================
.venv/lib/python3.12/site-packages/fireworks/client/image_api.py:131
  /home/arnold/Projects/experiments/ra-aid-workspace/.venv/lib/python3.12/site-packages/fireworks/client/image_api.py:131: PydanticDeprecatedSince20: Pydantic V1 style `@validat
    @validator("image_strength", pre=True, always=True)

.venv/lib/python3.12/site-packages/fireworks/client/image_api.py:139
  /home/arnold/Projects/experiments/ra-aid-workspace/.venv/lib/python3.12/site-packages/fireworks/client/image_api.py:139: PydanticDeprecatedSince20: Pydantic V1 style `@validat
    @validator("step_schedule_start", "step_schedule_end", pre=True, always=True)

.venv/lib/python3.12/site-packages/pydantic/_internal/_config.py:295
  /home/arnold/Projects/experiments/ra-aid-workspace/.venv/lib/python3.12/site-packages/pydantic/_internal/_config.py:295: PydanticDeprecatedSince20: Support for class-based `co
    warnings.warn(DEPRECATION_MESSAGE, DeprecationWarning)

.venv/lib/python3.12/site-packages/litellm/utils.py:171
  /home/arnold/Projects/experiments/ra-aid-workspace/.venv/lib/python3.12/site-packages/litellm/utils.py:171: DeprecationWarning: open_text is deprecated. Use files() instead. R
    with resources.open_text(

.venv/lib/python3.12/site-packages/litellm/caching/llm_caching_handler.py:18
  /home/arnold/Projects/experiments/ra-aid-workspace/.venv/lib/python3.12/site-packages/litellm/caching/llm_caching_handler.py:18: DeprecationWarning: There is no current event
    event_loop = asyncio.get_event_loop()

ra_aid/tools/handle_user_defined_test_cmd_execution.py:31
  /home/arnold/Projects/experiments/ra-aid-workspace/ra_aid/tools/handle_user_defined_test_cmd_execution.py:31: PytestCollectionWarning: cannot collect test class 'TestCommandEx
    class TestCommandExecutor:

ra_aid/tools/handle_user_defined_test_cmd_execution.py:21
  /home/arnold/Projects/experiments/ra-aid-workspace/ra_aid/tools/handle_user_defined_test_cmd_execution.py:21: PytestCollectionWarning: cannot collect test class 'TestState' because it has a __init__ constructor (from: tests/ra_aid/tools/test_handle_user_defined_test_cmd_execution.py)
    @dataclass

tests/ra_aid/database/test_migrations.py::TestIntegration::test_in_memory_migrations
  /home/arnold/Projects/experiments/ra-aid-workspace/.venv/lib/python3.12/site-packages/peewee.py:6437: DeprecationWarning: datetime.datetime.utcnow() is deprecated and scheduled for removal in a future version. Use timezone-aware objects to represent datetimes in UTC: datetime.datetime.now(datetime.UTC).
    dd[field_name] = default()

tests/ra_aid/tools/test_agent.py::test_request_research_uses_key_fact_repository
  /home/arnold/Projects/experiments/ra-aid-workspace/tests/ra_aid/tools/test_agent.py:234: LangChainDeprecationWarning: The method `BaseTool.__call__` was deprecated in langchain-core 0.1.47 and will be removed in 1.0. Use :meth:`~invoke` instead.
    result = request_research("test query")

-- Docs: https://docs.pytest.org/en/stable/how-to/capture-warnings.html
============================================================================ short test summary info ============================================================================
FAILED tests/ra_aid/test_credit_ui_helpers.py::test_escalate_context_length_error - AssertionError: assert 'Last error: context length exceeded' in '╭─────────────────────────────────── Error ────────────────────────────────────╮
│ [context length error] ...
ERROR tests/test_file_listing.py::test_get_file_listing[empty_repository] - FileNotFoundError: [Errno 2] No such file or directory: '/home/arnold/.openrouter_model_cache.json'
ERROR tests/test_file_listing.py::test_get_file_listing[single_file] - FileNotFoundError: [Errno 2] No such file or directory: '/home/arnold/.openrouter_model_cache.json'
ERROR tests/test_file_listing.py::test_get_file_listing[multiple_files] - FileNotFoundError: [Errno 2] No such file or directory: '/home/arnold/.openrouter_model_cache.json'
ERROR tests/test_file_listing.py::test_get_file_listing[duplicate_files] - FileNotFoundError: [Errno 2] No such file or directory: '/home/arnold/.openrouter_model_cache.json'
ERROR tests/test_file_listing.py::test_get_file_listing[with_limit] - FileNotFoundError: [Errno 2] No such file or directory: '/home/arnold/.openrouter_model_cache.json'
ERROR tests/test_file_listing.py::test_get_file_listing[with_empty_lines] - FileNotFoundError: [Errno 2] No such file or directory: '/home/arnold/.openrouter_model_cache.json'
ERROR tests/test_file_listing.py::test_get_file_listing[with_whitespace] - FileNotFoundError: [Errno 2] No such file or directory: '/home/arnold/.openrouter_model_cache.json'
ERROR tests/test_file_listing.py::test_get_file_listing[limit_larger_than_total] - FileNotFoundError: [Errno 2] No such file or directory: '/home/arnold/.openrouter_model_cache.json'
ERROR tests/test_file_listing.py::test_get_file_listing[limit_zero] - FileNotFoundError: [Errno 2] No such file or directory: '/home/arnold/.openrouter_model_cache.json'
ERROR tests/test_file_listing.py::test_get_file_listing[nested_paths] - FileNotFoundError: [Errno 2] No such file or directory: '/home/arnold/.openrouter_model_cache.json'
ERROR tests/test_file_listing.py::test_get_file_listing[special_characters] - FileNotFoundError: [Errno 2] No such file or directory: '/home/arnold/.openrouter_model_cache.json'
ERROR tests/test_file_listing.py::test_get_file_listing[duplicate_nested_paths] - FileNotFoundError: [Errno 2] No such file or directory: '/home/arnold/.openrouter_model_cache.json'
ERROR tests/test_file_listing.py::test_get_file_listing_non_git_repo - FileNotFoundError: [Errno 2] No such file or directory: '/home/arnold/.openrouter_model_cache.json'
ERROR tests/test_file_listing.py::test_get_file_listing_git_error - FileNotFoundError: [Errno 2] No such file or directory: '/home/arnold/.openrouter_model_cache.json'
ERROR tests/test_file_listing.py::test_get_file_listing_permission_error - FileNotFoundError: [Errno 2] No such file or directory: '/home/arnold/.openrouter_model_cache.json'
ERROR tests/test_file_listing.py::test_get_file_listing_unexpected_error - FileNotFoundError: [Errno 2] No such file or directory: '/home/arnold/.openrouter_model_cache.json'
======================================================= 1 failed, 701 passed, 6 skipped, 9 warnings, 16 errors in 25.19s ========================================================
