Fix these tests that fail:
>============================================================================ short test summary info ============================================================================
FAILED tests/ra_aid/test_credit_ui_helpers.py::test_escalate_context_length_error - AssertionError: assert 'Last error: context length exceeded' in '╭─────────────────────────────────── Error ────────────────────────────────────╮
│ [context length error] ...
FAILED tests/ra_aid/test_fallback_handler.py::TestFallbackHandler::test_attempt_fallback_resets_counter - AttributeError: 'NoneType' object has no attribute 'get_id'
FAILED tests/ra_aid/test_fallback_handler.py::TestFallbackHandler::test_invoke_fallback - AttributeError: 'NoneType' object has no attribute 'get_id'
FAILED tests/ra_aid/test_openrouter_cache.py::test_cache_error_handling - AssertionError: assert {'model/ttl':...n': 3.2, ...}} == {}
FAILED tests/ra_aid/test_token_usage_tracking.py::test_token_usage_storage - AssertionError: TrajectoryRepository.create was not called
FAILED tests/ra_aid/test_tool_configs.py::test_get_research_tools - RuntimeError: ConfigRepository not initialized in current context. Make sure to use ConfigRepositoryManager.
FAILED tests/ra_aid/test_tool_configs.py::test_get_planning_tools - RuntimeError: ConfigRepository not initialized in current context. Make sure to use ConfigRepositoryManager.
FAILED tests/ra_aid/test_tool_configs.py::test_get_implementation_tools - RuntimeError: ConfigRepository not initialized in current context. Make sure to use ConfigRepositoryManager.
FAILED tests/ra_aid/test_tool_configs.py::test_get_web_research_tools - RuntimeError: ConfigRepository not initialized in current context. Make sure to use ConfigRepositoryManager.
